C:\Python39\derating>pyinstaller -F derating.py  --hidden-import="resource"
76 INFO: PyInstaller: 5.0.dev0
76 INFO: Python: 3.9.7
85 INFO: Platform: Windows-10-10.0.19042-SP0
86 INFO: wrote C:\Python39\derating\derating.spec
130 INFO: UPX is available.
132 INFO: Extending PYTHONPATH with paths
['C:\\Python39\\derating']
560 INFO: checking Analysis
561 INFO: Building Analysis because Analysis-00.toc is non existent
561 INFO: Initializing module dependency graph...
563 INFO: Caching module graph hooks...
588 INFO: Analyzing base_library.zip ...
2651 INFO: Processing pre-find module path hook distutils from 'c:\\python39\\lib\\site-packages\\PyInstaller\\hooks\\pre_find_module_path\\hook-distutils.py'.
2652 INFO: distutils: retargeting to non-venv dir 'c:\\python39\\lib'
5705 INFO: Caching module dependency graph...
5854 INFO: running Analysis Analysis-00.toc
5873 INFO: Adding Microsoft.Windows.Common-Controls to dependent assemblies of final executable
  required by c:\python39\python.exe
5932 INFO: Analyzing C:\Python39\derating\derating.py
7035 INFO: Processing pre-find module path hook site from 'c:\\python39\\lib\\site-packages\\PyInstaller\\hooks\\pre_find_module_path\\hook-site.py'.
7036 INFO: site: retargeting to fake-dir 'c:\\python39\\lib\\site-packages\\PyInstaller\\fake-modules'
10197 INFO: Processing pre-safe import module hook urllib3.packages.six.moves from 'c:\\python39\\lib\\site-packages\\PyInstaller\\hooks\\pre_safe_import_module\\hook-urllib3.packages.six.moves.py'.
17116 INFO: Processing pre-safe import module hook six.moves from 'c:\\python39\\lib\\site-packages\\PyInstaller\\hooks\\pre_safe_import_module\\hook-six.moves.py'.
c:\python39\lib\site-packages\xlsxwriter\worksheet.py:358: SyntaxWarning: "is" with a literal. Did you mean "=="?
  if token is '':
c:\python39\lib\site-packages\xlsxwriter\worksheet.py:2437: SyntaxWarning: "is" with a literal. Did you mean "=="?
  if options['min_type'] is 'min' and options['min_value'] == 0:
c:\python39\lib\site-packages\xlsxwriter\worksheet.py:2440: SyntaxWarning: "is" with a literal. Did you mean "=="?
  if options['max_type'] is 'max' and options['max_value'] == 0:
c:\python39\lib\site-packages\xlsxwriter\worksheet.py:4999: SyntaxWarning: "is" with a literal. Did you mean "=="?
  if props[i]['type'] is 'number':
c:\python39\lib\site-packages\xlsxwriter\worksheet.py:6827: SyntaxWarning: "is not" with a literal. Did you mean "!="?
  if data_bar['bar_axis_position'] is not 'none':
c:\python39\lib\site-packages\xlsxwriter\worksheet.py:6862: SyntaxWarning: "is" with a literal. Did you mean "=="?
  if data_bar['bar_direction'] is 'left':
c:\python39\lib\site-packages\xlsxwriter\worksheet.py:6865: SyntaxWarning: "is" with a literal. Did you mean "=="?
  if data_bar['bar_direction'] is 'right':
c:\python39\lib\site-packages\xlsxwriter\worksheet.py:6875: SyntaxWarning: "is" with a literal. Did you mean "=="?
  if data_bar['bar_axis_position'] is 'middle':
c:\python39\lib\site-packages\xlsxwriter\worksheet.py:6878: SyntaxWarning: "is" with a literal. Did you mean "=="?
  if data_bar['bar_axis_position'] is 'none':
c:\python39\lib\site-packages\xlsxwriter\chart.py:2497: SyntaxWarning: "is" with a literal. Did you mean "=="?
  if val is 'right':
c:\python39\lib\site-packages\xlsxwriter\chart.py:2500: SyntaxWarning: "is" with a literal. Did you mean "=="?
  if val is 'left':
34326 INFO: Processing module hooks...
34326 INFO: Loading module hook 'hook-bcrypt.py' from 'c:\\python39\\lib\\site-packages\\_pyinstaller_hooks_contrib\\hooks\\stdhooks'...
34327 INFO: Loading module hook 'hook-certifi.py' from 'c:\\python39\\lib\\site-packages\\_pyinstaller_hooks_contrib\\hooks\\stdhooks'...
34333 INFO: Loading module hook 'hook-cryptography.py' from 'c:\\python39\\lib\\site-packages\\_pyinstaller_hooks_contrib\\hooks\\stdhooks'...
34937 INFO: Loading module hook 'hook-IPython.py' from 'c:\\python39\\lib\\site-packages\\_pyinstaller_hooks_contrib\\hooks\\stdhooks'...
Traceback (most recent call last):
  File "c:\python39\lib\site-packages\PyInstaller\utils\hooks\__init__.py", line 390, in get_module_file_attribute
    filename = _get_module_file_attribute(package)
  File "c:\python39\lib\site-packages\PyInstaller\isolated\_parent.py", line 266, in wrapped
    return call(function, *args, **kwargs)
  File "c:\python39\lib\site-packages\PyInstaller\isolated\_parent.py", line 235, in call
    return isolated.call(function, *args, **kwargs)
  File "c:\python39\lib\site-packages\PyInstaller\isolated\_parent.py", line 173, in call
    raise RuntimeError(f"Child process call to {function.__name__}() failed with:\n" + output)
RuntimeError: Child process call to _get_module_file_attribute() failed with:
  File "c:\python39\lib\site-packages\IPython\utils\timing.py", line 27, in <module>
    import resource
ModuleNotFoundError: No module named 'resource'

During handling of the above exception, another exception occurred:

Traceback (most recent call last):
  File "c:\python39\lib\site-packages\PyInstaller\isolated\_child.py", line 59, in run_next_command
    output = function(*args, **kwargs)
  File "c:\python39\lib\site-packages\PyInstaller\utils\hooks\__init__.py", line 385, in _get_module_file_attribute
    p = importlib.import_module(package)
  File "c:\python39\lib\importlib\__init__.py", line 127, in import_module
    return _bootstrap._gcd_import(name[level:], package, level)
  File "<frozen importlib._bootstrap>", line 1030, in _gcd_import
  File "<frozen importlib._bootstrap>", line 1007, in _find_and_load
  File "<frozen importlib._bootstrap>", line 972, in _find_and_load_unlocked
  File "<frozen importlib._bootstrap>", line 228, in _call_with_frames_removed
  File "<frozen importlib._bootstrap>", line 1030, in _gcd_import
  File "<frozen importlib._bootstrap>", line 1007, in _find_and_load
  File "<frozen importlib._bootstrap>", line 986, in _find_and_load_unlocked
  File "<frozen importlib._bootstrap>", line 680, in _load_unlocked
  File "<frozen importlib._bootstrap_external>", line 850, in exec_module
  File "<frozen importlib._bootstrap>", line 228, in _call_with_frames_removed
  File "c:\python39\lib\site-packages\IPython\__init__.py", line 49, in <module>
    from .terminal.embed import embed
  File "c:\python39\lib\site-packages\IPython\terminal\embed.py", line 19, in <module>
    from IPython.terminal.ipapp import load_default_config
  File "c:\python39\lib\site-packages\IPython\terminal\ipapp.py", line 30, in <module>
    from IPython.core.magics import ScriptMagics
  File "c:\python39\lib\site-packages\IPython\core\magics\__init__.py", line 21, in <module>
    from .execution import ExecutionMagics
  File "c:\python39\lib\site-packages\IPython\core\magics\execution.py", line 46, in <module>
    from IPython.utils.timing import clock, clock2
  File "c:\python39\lib\site-packages\IPython\utils\timing.py", line 64, in <module>
    clocku = clocks = clock = time.clock
AttributeError: module 'time' has no attribute 'clock'

The above exception was the direct cause of the following exception:

Traceback (most recent call last):
  File "c:\python39\lib\site-packages\PyInstaller\depend\imphook.py", line 361, in _load_hook_module
    self._hook_module = importlib_load_source(self.hook_module_name, self.hook_filename)
  File "c:\python39\lib\site-packages\PyInstaller\compat.py", line 620, in importlib_load_source
    return mod_loader.load_module()
  File "<frozen importlib._bootstrap_external>", line 529, in _check_name_wrapper
  File "<frozen importlib._bootstrap_external>", line 1029, in load_module
  File "<frozen importlib._bootstrap_external>", line 854, in load_module
  File "<frozen importlib._bootstrap>", line 274, in _load_module_shim
  File "<frozen importlib._bootstrap>", line 711, in _load
  File "<frozen importlib._bootstrap>", line 680, in _load_unlocked
  File "<frozen importlib._bootstrap_external>", line 850, in exec_module
  File "<frozen importlib._bootstrap>", line 228, in _call_with_frames_removed
  File "c:\python39\lib\site-packages\_pyinstaller_hooks_contrib\hooks\stdhooks\hook-IPython.py", line 34, in <module>
    datas += collect_data_files('IPython.extensions', include_py_files=True)
  File "c:\python39\lib\site-packages\PyInstaller\utils\hooks\__init__.py", line 744, in collect_data_files
    pkg_base, pkg_dir = get_package_paths(package)
  File "c:\python39\lib\site-packages\PyInstaller\utils\hooks\__init__.py", line 534, in get_package_paths
    file_attr = get_module_file_attribute(package)
  File "c:\python39\lib\site-packages\PyInstaller\utils\hooks\__init__.py", line 392, in get_module_file_attribute
    raise ImportError(f"Failed to obtain the __file__ attribute of package/module {package}!") from e
ImportError: Failed to obtain the __file__ attribute of package/module IPython.extensions!

During handling of the above exception, another exception occurred:

Traceback (most recent call last):
  File "c:\python39\lib\runpy.py", line 197, in _run_module_as_main
    return _run_code(code, main_globals, None,
  File "c:\python39\lib\runpy.py", line 87, in _run_code
    exec(code, run_globals)
  File "C:\Python39\Scripts\pyinstaller.exe\__main__.py", line 7, in <module>
  File "c:\python39\lib\site-packages\PyInstaller\__main__.py", line 124, in run
    run_build(pyi_config, spec_file, **vars(args))
  File "c:\python39\lib\site-packages\PyInstaller\__main__.py", line 58, in run_build
    PyInstaller.building.build_main.main(pyi_config, spec_file, **kwargs)
  File "c:\python39\lib\site-packages\PyInstaller\building\build_main.py", line 818, in main
    build(specfile, kw.get('distpath'), kw.get('workpath'), kw.get('clean_build'))
  File "c:\python39\lib\site-packages\PyInstaller\building\build_main.py", line 750, in build
    exec(code, spec_namespace)
  File "C:\Python39\derating\derating.spec", line 7, in <module>
    a = Analysis(
  File "c:\python39\lib\site-packages\PyInstaller\building\build_main.py", line 302, in __init__
    self.__postinit__()
  File "c:\python39\lib\site-packages\PyInstaller\building\datastruct.py", line 155, in __postinit__
    self.assemble()
  File "c:\python39\lib\site-packages\PyInstaller\building\build_main.py", line 470, in assemble
    self.graph.process_post_graph_hooks(self)
  File "c:\python39\lib\site-packages\PyInstaller\depend\analysis.py", line 326, in process_post_graph_hooks
    module_hook.post_graph(analysis)
  File "c:\python39\lib\site-packages\PyInstaller\depend\imphook.py", line 398, in post_graph
    self._load_hook_module()
  File "c:\python39\lib\site-packages\PyInstaller\depend\imphook.py", line 364, in _load_hook_module
    raise ImportErrorWhenRunningHook(self.hook_module_name, self.hook_filename)
PyInstaller.exceptions.ImportErrorWhenRunningHook: Failed to import module __PyInstaller_hooks_0_IPython required by hook for module c:\python39\lib\site-packages\_pyinstaller_hooks_contrib\hooks\stdhooks\hook-IPython.py. Please check whether module __PyInstaller_hooks_0_IPython actually exists and whether the hook is compatible with your version of c:\python39\lib\site-packages\_pyinstaller_hooks_contrib\hooks\stdhooks\hook-IPython.py: You might want to read more about hooks in the manual and provide a pull-request to improve PyInstaller.

C:\Python39\derating>